Workbook

Sheet Template
A1: code | B1: name | C1: category | D1: unit_price | E1: description | F1: notes | G1: attr_name_1 | H1: attr_value_1 | I1: attr_unit_1 | J1: attr_type_1 | K1: attr_name_2 | L1: attr_value_2 | M1: attr_unit_2 | N1: attr_type_2 | O1: attr_name_3 | P1: attr_value_3 | Q1: attr_unit_3 | R1: attr_type_3 | S1: attr_name_4 | T1: attr_value_4 | U1: attr_unit_4 | V1: attr_type_4
A2: ="OBR-"&SUBSTITUTE(SUBSTITUTE(SUBSTITUTE(B2," ","-"),"R-","BE-"),"-OBR","") -> OBR-BE-H-204 | B2: R H 204 OBR | C2: Manşonlar | D2: =VLOOKUP(A2,Sayfa2!C:D,2,0) -> 0.54 | G2: Ağırlık | H2: =VLOOKUP(A2,Sayfa2!A:B,2,0) -> 0.041 | I2: KG | J2: number
A3: ="OBR-"&SUBSTITUTE(SUBSTITUTE(SUBSTITUTE(B3," ","-"),"R-","BE-"),"-OBR","") -> OBR-BE-H-205 | B3: R H 205 OBR | C3: Manşonlar | D3: =VLOOKUP(A3,Sayfa2!C:D,2,0) -> 0.49 | G3: Ağırlık | H3: =VLOOKUP(A3,Sayfa2!A:B,2,0) -> 0.07 | I3: KG | J3: number
A4: ="OBR-"&SUBSTITUTE(SUBSTITUTE(SUBSTITUTE(B4," ","-"),"R-","BE-"),"-OBR","") -> OBR-BE-H-206 | B4: R H 206 OBR | C4: Manşonlar | D4: =VLOOKUP(A4,Sayfa2!C:D,2,0) -> 0.51 | G4: Ağırlık | H4: =VLOOKUP(A4,Sayfa2!A:B,2,0) -> 0.1 | I4: KG | J4: number
A5: ="OBR-"&SUBSTITUTE(SUBSTITUTE(SUBSTITUTE(B5," ","-"),"R-","BE-"),"-OBR","") -> OBR-BE-H-207 | B5: R H 207 OBR | C5: Manşonlar | D5: =VLOOKUP(A5,Sayfa2!C:D,2,0) -> 0.57 | G5: Ağırlık | H5: =VLOOKUP(A5,Sayfa2!A:B,2,0) -> 0.13 | I5: KG | J5: number
A6: ="OBR-"&SUBSTITUTE(SUBSTITUTE(SUBSTITUTE(B6," ","-"),"R-","BE-"),"-OBR","") -> OBR-BE-H-208 | B6: R H 208 OBR | C6: Manşonlar | D6: =VLOOKUP(A6,Sayfa2!C:D,2,0) -> 0.62 | G6: Ağırlık | H6: =VLOOKUP(A6,Sayfa2!A:B,2,0) -> 0.17 | I6: KG | J6: number
A7: ="OBR-"&SUBSTITUTE(SUBSTITUTE(SUBSTITUTE(B7," ","-"),"R-","BE-"),"-OBR","") -> OBR-BE-H-209 | B7: R H 209 OBR | C7: Manşonlar | D7: =VLOOKUP(A7,Sayfa2!C:D,2,0) -> 0.72 | G7: Ağırlık | H7: =VLOOKUP(A7,Sayfa2!A:B,2,0) -> 0.23 | I7: KG | J7: number
A8: ="OBR-"&SUBSTITUTE(SUBSTITUTE(SUBSTITUTE(B8," ","-"),"R-","BE-"),"-OBR","") -> OBR-BE-H-210 | B8: R H 210 OBR | C8: Manşonlar | D8: =VLOOKUP(A8,Sayfa2!C:D,2,0) -> 0.82 | G8: Ağırlık | H8: =VLOOKUP(A8,Sayfa2!A:B,2,0) -> 0.27 | I8: KG | J8: number
A9: ="OBR-"&SUBSTITUTE(SUBSTITUTE(SUBSTITUTE(B9," ","-"),"R-","BE-"),"-OBR","") -> OBR-BE-H-211 | B9: R H 211 OBR | C9: Manşonlar | D9: =VLOOKUP(A9,Sayfa2!C:D,2,0) -> 0.92 | G9: Ağırlık | H9: =VLOOKUP(A9,Sayfa2!A:B,2,0) -> 0.31 | I9: KG | J9: number
A10: ="OBR-"&SUBSTITUTE(SUBSTITUTE(SUBSTITUTE(B10," ","-"),"R-","BE-"),"-OBR","") -> OBR-BE-H-212 | B10: R H 212 OBR | C10: Manşonlar | D10: =VLOOKUP(A10,Sayfa2!C:D,2,0) -> 1.05 | G10: Ağırlık | H10: =VLOOKUP(A10,Sayfa2!A:B,2,0) -> 0.35 | I10: KG | J10: number
A11: ="OBR-"&SUBSTITUTE(SUBSTITUTE(SUBSTITUTE(B11," ","-"),"R-","BE-"),"-OBR","") -> OBR-BE-H-213 | B11: R H 213 OBR | C11: Manşonlar | D11: =VLOOKUP(A11,Sayfa2!C:D,2,0) -> 1.19 | G11: Ağırlık | H11: =VLOOKUP(A11,Sayfa2!A:B,2,0) -> 0.4 | I11: KG | J11: number
A12: ="OBR-"&SUBSTITUTE(SUBSTITUTE(SUBSTITUTE(B12," ","-"),"R-","BE-"),"-OBR","") -> OBR-BE-H-214 | B12: R H 214 OBR | C12: Manşonlar | D12: =VLOOKUP(A12,Sayfa2!C:D,2,0) -> 1.76 | G12: Ağırlık | H12: =VLOOKUP(A12,Sayfa2!A:B,2,0) -> 0.6 | I12: KG | J12: number
A13: ="OBR-"&SUBSTITUTE(SUBSTITUTE(SUBSTITUTE(B13," ","-"),"R-","BE-"),"-OBR","") -> OBR-BE-H-215 | B13: R H 215 OBR | C13: Manşonlar | D13: =VLOOKUP(A13,Sayfa2!C:D,2,0) -> 1.88 | G13: Ağırlık | H13: =VLOOKUP(A13,Sayfa2!A:B,2,0) -> 0.71 | I13: KG | J13: number
... A69: ="OBR-"&SUBSTITUTE(SUBSTITUTE(SUBSTITUTE(B69," ","-"),"R-","BE-"),"-OBR","") -> OBR-BE-H-2340 | B69: R H 2340 OBR | C69: Manşonlar | D69: =VLOOKUP(A69,Sayfa2!C:D,2,0) -> 50.37 | G69: Ağırlık | H69: =VLOOKUP(A69,Sayfa2!A:B,2,0) -> 14 | I69: KG | J69: number
A70: ="OBR-"&SUBSTITUTE(SUBSTITUTE(SUBSTITUTE(TRIM(B70)," ","-"),"R-","BE-"),"-OBR","") -> OBR-BE-SN-505 | B70: R SN 505 | C70: SN-SNH Rulmanlar | D70: =VLOOKUP(A70,Sayfa2!C:D,2,0) -> 3.21 | G70: Ağırlık | H70: =VLOOKUP(A70,Sayfa2!A:B,2,0) -> 0 | I70: KG | J70: number
A71: ="OBR-"&SUBSTITUTE(SUBSTITUTE(SUBSTITUTE(TRIM(B71)," ","-"),"R-","BE-"),"-OBR","") -> OBR-BE-SN-506 | B71: R SN 506 | C71: SN-SNH Rulmanlar | D71: =VLOOKUP(A71,Sayfa2!C:D,2,0) -> 3.21 | G71: Ağırlık | H71: =VLOOKUP(A71,Sayfa2!A:B,2,0) -> 0 | I71: KG | J71: number
A72: ="OBR-"&SUBSTITUTE(SUBSTITUTE(SUBSTITUTE(TRIM(B72)," ","-"),"R-","BE-"),"-OBR","") -> OBR-BE-SN-507 | B72: R SN 507 | C72: SN-SNH Rulmanlar | D72: =VLOOKUP(A72,Sayfa2!C:D,2,0) -> 3.57 | G72: Ağırlık | H72: =VLOOKUP(A72,Sayfa2!A:B,2,0) -> 0 | I72: KG | J72: number
A73: ="OBR-"&SUBSTITUTE(SUBSTITUTE(SUBSTITUTE(TRIM(B73)," ","-"),"R-","BE-"),"-OBR","") -> OBR-BE-SN-508 | B73: R SN 508 | C73: SN-SNH Rulmanlar | D73: =VLOOKUP(A73,Sayfa2!C:D,2,0) -> 4.02 | G73: Ağırlık | H73: =VLOOKUP(A73,Sayfa2!A:B,2,0) -> 0 | I73: KG | J73: number
A74: ="OBR-"&SUBSTITUTE(SUBSTITUTE(SUBSTITUTE(TRIM(B74)," ","-"),"R-","BE-"),"-OBR","") -> OBR-BE-SN-509 | B74: R SN 509 | C74: SN-SNH Rulmanlar | D74: =VLOOKUP(A74,Sayfa2!C:D,2,0) -> 4.2 | G74: Ağırlık | H74: =VLOOKUP(A74,Sayfa2!A:B,2,0) -> 0 | I74: KG | J74: number
A75: ="OBR-"&SUBSTITUTE(SUBSTITUTE(SUBSTITUTE(TRIM(B75)," ","-"),"R-","BE-"),"-OBR","") -> OBR-BE-SN-510 | B75: R SN 510 | C75: SN-SNH Rulmanlar | D75: =VLOOKUP(A75,Sayfa2!C:D,2,0) -> 4.55 | G75: Ağırlık | H75: =VLOOKUP(A75,Sayfa2!A:B,2,0) -> 0 | I75: KG | J75: number
A76: ="OBR-"&SUBSTITUTE(SUBSTITUTE(SUBSTITUTE(TRIM(B76)," ","-"),"R-","BE-"),"-OBR","") -> OBR-BE-SN-511 | B76: R SN 511 | C76: SN-SNH Rulmanlar | D76: =VLOOKUP(A76,Sayfa2!C:D,2,0) -> 5.36 | G76: Ağırlık | H76: =VLOOKUP(A76,Sayfa2!A:B,2,0) -> 0 | I76: KG | J76: number
A77: ="OBR-"&SUBSTITUTE(SUBSTITUTE(SUBSTITUTE(TRIM(B77)," ","-"),"R-","BE-"),"-OBR","") -> OBR-BE-SN-512 | B77: R SN 512 | C77: SN-SNH Rulmanlar | D77: =VLOOKUP(A77,Sayfa2!C:D,2,0) -> 5.89 | G77: Ağırlık | H77: =VLOOKUP(A77,Sayfa2!A:B,2,0) -> 0 | I77: KG | J77: number
A78: ="OBR-"&SUBSTITUTE(SUBSTITUTE(SUBSTITUTE(TRIM(B78)," ","-"),"R-","BE-"),"-OBR","") -> OBR-BE-SN-513 | B78: R SN 513 | C78: SN-SNH Rulmanlar | D78: =VLOOKUP(A78,Sayfa2!C:D,2,0) -> 7.5 | G78: Ağırlık | H78: =VLOOKUP(A78,Sayfa2!A:B,2,0) -> 0 | I78: KG | J78: number
A79: ="OBR-"&SUBSTITUTE(SUBSTITUTE(SUBSTITUTE(TRIM(B79)," ","-"),"R-","BE-"),"-OBR","") -> OBR-BE-SN-514 | B79: R SN 514 | C79: SN-SNH Rulmanlar | D79: =VLOOKUP(A79,Sayfa2!C:D,2,0) -> 8.57 | G79: Ağırlık | H79: =VLOOKUP(A79,Sayfa2!A:B,2,0) -> 0 | I79: KG | J79: number
A80: ="OBR-"&SUBSTITUTE(SUBSTITUTE(SUBSTITUTE(TRIM(B80)," ","-"),"R-","BE-"),"-OBR","") -> OBR-BE-SN-515 | B80: R SN 515 | C80: SN-SNH Rulmanlar | D80: =VLOOKUP(A80,Sayfa2!C:D,2,0) -> 8.57 | G80: Ağırlık | H80: =VLOOKUP(A80,Sayfa2!A:B,2,0) -> 0 | I80: KG | J80: number
A81: ="OBR-"&SUBSTITUTE(SUBSTITUTE(SUBSTITUTE(TRIM(B81)," ","-"),"R-","BE-"),"-OBR","") -> OBR-BE-SN-516 | B81: R SN 516 | C81: SN-SNH Rulmanlar | D81: =VLOOKUP(A81,Sayfa2!C:D,2,0) -> 10 | G81: Ağırlık | H81: =VLOOKUP(A81,Sayfa2!A:B,2,0) -> 0 | I81: KG | J81: number
... A106: ="OBR-"&SUBSTITUTE(SUBSTITUTE(SUBSTITUTE(TRIM(B106)," ","-"),"R-","BE-"),"-OBR","") -> OBR-BE-SNH-526 | B106: R SNH 526 | C106: SN-SNH Rulmanlar | D106: =VLOOKUP(A106,Sayfa2!C:D,2,0) -> 51.79 | G106: Ağırlık | H106: =VLOOKUP(A106,Sayfa2!A:B,2,0) -> 0 | I106: KG | J106: number
A107: OBR-BE-GU-1000 | B107: R GU 1000 OBR | C107: İstavrozlar | D107: =VLOOKUP(A107,Sayfa2!C:D,2,0) -> 1.35 | G107: Ağırlık | H107: =VLOOKUP(A107,Sayfa2!A:B,2,0) -> 0.48 | I107: KG | J107: number
A108: OBR-BE-GU-1000-C | B108: R GU 1000 C OBR | C108: İstavrozlar | D108: =VLOOKUP(A108,Sayfa2!C:D,2,0) -> 1.52 | G108: Ağırlık | H108: =VLOOKUP(A108,Sayfa2!A:B,2,0) -> 0.48 | I108: KG | J108: number
A109: TAW-BE-GU-1000-C | B109: R GU 1000 C TAW | C109: İstavrozlar | D109: =VLOOKUP(A109,Sayfa2!C:D,2,0) -> 1.52 | G109: Ağırlık | H109: =VLOOKUP(A109,Sayfa2!A:B,2,0) -> 0.48 | I109: KG | J109: number
A110: OBR-BE-GU-1100 | B110: R GU 1100 OBR | C110: İstavrozlar | D110: =VLOOKUP(A110,Sayfa2!C:D,2,0) -> 1.35 | G110: Ağırlık | H110: =VLOOKUP(A110,Sayfa2!A:B,2,0) -> 0.4 | I110: KG | J110: number
A111: OBR-BE-GU-1100-C | B111: R GU 1100 C OBR | C111: İstavrozlar | D111: =VLOOKUP(A111,Sayfa2!C:D,2,0) -> 1.35 | G111: Ağırlık | H111: =VLOOKUP(A111,Sayfa2!A:B,2,0) -> 0.4 | I111: KG | J111: number
A112: TAW-BE-GU-1100-C | B112: R GU 1100 C TAW | C112: İstavrozlar | D112: =VLOOKUP(A112,Sayfa2!C:D,2,0) -> 1.35 | G112: Ağırlık | H112: =VLOOKUP(A112,Sayfa2!A:B,2,0) -> 0.4 | I112: KG | J112: number
A113: OBR-BE-GU-1100-T | B113: R GU 1100 T OBR | C113: İstavrozlar | D113: =VLOOKUP(A113,Sayfa2!C:D,2,0) -> 1.35 | G113: Ağırlık | H113: =VLOOKUP(A113,Sayfa2!A:B,2,0) -> 0.4 | I113: KG | J113: number
A114: OBR-BE-GU-1380-C | B114: R GU 1380 C OBR | C114: İstavrozlar | D114: =VLOOKUP(A114,Sayfa2!C:D,2,0) -> 0.93 | G114: Ağırlık | H114: =VLOOKUP(A114,Sayfa2!A:B,2,0) -> 0.215 | I114: KG | J114: number
A115: TAW-BE-GU-1380-C | B115: R GU 1380 C TAW | C115: İstavrozlar | D115: =VLOOKUP(A115,Sayfa2!C:D,2,0) -> 0.93 | G115: Ağırlık | H115: =VLOOKUP(A115,Sayfa2!A:B,2,0) -> 0.215 | I115: KG | J115: number
A116: OBR-BE-GU-1700-C | B116: R GU 1700 C OBR | C116: İstavrozlar | D116: =VLOOKUP(A116,Sayfa2!C:D,2,0) -> 0.93 | G116: Ağırlık | H116: =VLOOKUP(A116,Sayfa2!A:B,2,0) -> 0.216 | I116: KG | J116: number
A117: TAW-BE-GU-1700-C | B117: R GU 1700 C TAW | C117: İstavrozlar | D117: =VLOOKUP(A117,Sayfa2!C:D,2,0) -> 0.93 | G117: Ağırlık | H117: =VLOOKUP(A117,Sayfa2!A:B,2,0) -> 0.216 | I117: KG | J117: number
A118: OBR-BE-GU-1740 | B118: R GU 1740 OBR | C118: İstavrozlar | D118: =VLOOKUP(A118,Sayfa2!C:D,2,0) -> 1.88 | G118: Ağırlık | H118: =VLOOKUP(A118,Sayfa2!A:B,2,0) -> 0.63 | I118: KG | J118: number
... A191: TAW-QC-1-1/4-F | B191: 824A-11 1-1/4 G DISI | C191: Jaklar | D191: =VLOOKUP(A191,Sayfa2!C:D,2,0) -> 0 | G191: Ağırlık | H191: =VLOOKUP(A191,Sayfa2!A:B,2,0) -> 0 | I191: KG | J191: number
...

Sheet Sayfa2
B3: KG | D3: LHZ 21-10-2015
B4: KİLOSU
A5: OBR-BE-H-204 | B5: 0.041 | C5: OBR-BE-H-204 | D5: 0.54
A6: OBR-BE-H-205 | B6: 0.07 | C6: OBR-BE-H-205 | D6: 0.49
A7: OBR-BE-H-206 | B7: 0.1 | C7: OBR-BE-H-206 | D7: 0.51
A8: OBR-BE-H-207 | B8: 0.13 | C8: OBR-BE-H-207 | D8: 0.57
A9: OBR-BE-H-208 | B9: 0.17 | C9: OBR-BE-H-208 | D9: 0.62
A10: OBR-BE-H-209 | B10: 0.23 | C10: OBR-BE-H-209 | D10: 0.72
A11: OBR-BE-H-210 | B11: 0.27 | C11: OBR-BE-H-210 | D11: 0.82
A12: OBR-BE-H-211 | B12: 0.31 | C12: OBR-BE-H-211 | D12: 0.92
A13: OBR-BE-H-212 | B13: 0.35 | C13: OBR-BE-H-212 | D13: 1.05
A14: OBR-BE-H-213 | B14: 0.4 | C14: OBR-BE-H-213 | D14: 1.19
A15: OBR-BE-H-214 | B15: 0.6 | C15: OBR-BE-H-214 | D15: 1.76
A16: OBR-BE-H-215 | B16: 0.71 | C16: OBR-BE-H-215 | D16: 1.88
... A43: OBR-BE-H-3128 | B43: 4.33 | C43: OBR-BE-H-3128 | D43: 17.8
A44: OBR-BE-H-3130 | B44: 5.49 | C44: OBR-BE-H-3130
A45: OBR-BE-H-3132 | B45: 7.57 | C45: OBR-BE-H-3132 | D45: 26.31
A46: OBR-BE-H-2304 | B46: 0.047 | C46: OBR-BE-H-2304 | D46: 0.64
A47: OBR-BE-H-2305 | B47: 0.087 | C47: OBR-BE-H-2305 | D47: 0.59
A48: OBR-BE-H-2306 | B48: 0.117 | C48: OBR-BE-H-2306 | D48: 0.61
A49: OBR-BE-H-2307 | B49: 0.171 | C49: OBR-BE-H-2307 | D49: 0.66
A50: OBR-BE-H-2308 | B50: 0.222 | C50: OBR-BE-H-2308 | D50: 0.8
A51: OBR-BE-H-2309 | B51: 0.28 | C51: OBR-BE-H-2309 | D51: 0.86
A52: OBR-BE-H-2310 | B52: 0.353 | C52: OBR-BE-H-2310 | D52: 0.98
A53: OBR-BE-H-2311 | B53: 0.426 | C53: OBR-BE-H-2311 | D53: 1.15
A54: OBR-BE-H-2312 | B54: 0.533 | C54: OBR-BE-H-2312 | D54: 1.39
A55: OBR-BE-H-2313 | B55: 0.553 | C55: OBR-BE-H-2313 | D55: 1.6
A56: OBR-BE-H-2314 | B56: 0.895 | C56: OBR-BE-H-2314 | D56: 2.44
... A72: OBR-BE-H-2340 | B72: 14 | C72: OBR-BE-H-2340 | D72: 50.37
A73: OBR-BE-SN-505 | C73: OBR-BE-SN-505 | D73: 3.21
A74: OBR-BE-SN-506 | C74: OBR-BE-SN-506 | D74: 3.21
A75: OBR-BE-SN-507 | C75: OBR-BE-SN-507 | D75: 3.57
A76: OBR-BE-SN-508 | C76: OBR-BE-SN-508 | D76: 4.02
A77: OBR-BE-SN-509 | C77: OBR-BE-SN-509 | D77: 4.2
A78: OBR-BE-SN-510 | C78: OBR-BE-SN-510 | D78: 4.55
A79: OBR-BE-SN-511 | C79: OBR-BE-SN-511 | D79: 5.36
A80: OBR-BE-SN-512 | C80: OBR-BE-SN-512 | D80: 5.89
A81: OBR-BE-SN-513 | C81: OBR-BE-SN-513 | D81: 7.5
A82: OBR-BE-SN-514 | C82: OBR-BE-SN-514 | D82: 8.57
A83: OBR-BE-SN-515 | C83: OBR-BE-SN-515 | D83: 8.57
...
